{"label": "test_search_in_python_org", "file": "/Users/sidnarang/Desktop/JWC_SN/jenkins/2016-09-14_09-57-40.007266/classes/test_SeleniumDemo.py", "full_name": "test_SeleniumDemo.PythonOrgSearch.test_search_in_python_org", "status": "BROKEN", "description": null, "start_time": 1473872260.500894, "duration": 9.11159086227417, "error_msg": "WebDriverException: Message: The browser appears to have exited before we could connect. If you specified a log_file in the FirefoxBinary constructor, check it for details.", "error_trace": "Traceback (most recent call last):\n  File \"/System/Library/Frameworks/Python.framework/Versions/2.7/lib/python2.7/unittest/case.py\", line 322, in run\n    self.setUp()\n  File \"/Users/sidnarang/Desktop/JWC_SN/jenkins/2016-09-14_09-57-40.007266/classes/test_SeleniumDemo.py\", line 9, in setUp\n    self.driver = webdriver.Firefox()\n  File \"/Library/Python/2.7/site-packages/selenium/webdriver/firefox/webdriver.py\", line 80, in __init__\n    self.binary, timeout)\n  File \"/Library/Python/2.7/site-packages/selenium/webdriver/firefox/extension_connection.py\", line 52, in __init__\n    self.binary.launch_browser(self.profile, timeout=timeout)\n  File \"/Library/Python/2.7/site-packages/selenium/webdriver/firefox/firefox_binary.py\", line 68, in launch_browser\n    self._wait_until_connectable(timeout=timeout)\n  File \"/Library/Python/2.7/site-packages/selenium/webdriver/firefox/firefox_binary.py\", line 99, in _wait_until_connectable\n    \"The browser appears to have exited \"\nWebDriverException: Message: The browser appears to have exited before we could connect. If you specified a log_file in the FirefoxBinary constructor, check it for details."}
{"label": "test_search_in_python_org", "file": "/Users/sidnarang/Desktop/JWC_SN/jenkins/2016-09-14_09-57-40.007266/classes/test_SeleniumDemo.py", "full_name": "test_SeleniumDemo.PythonOrgSearch.test_search_in_python_org", "status": "BROKEN", "description": null, "start_time": 1473872269.618249, "duration": 30.197680950164795, "error_msg": "WebDriverException: Message: Can't load the profile. Profile Dir: /var/folders/rz/llsy0wqx4zn6qw066kpv7l8r0000gn/T/tmp56XwRj If you specified a log_file in the FirefoxBinary constructor, check it for details.", "error_trace": "Traceback (most recent call last):\n  File \"/System/Library/Frameworks/Python.framework/Versions/2.7/lib/python2.7/unittest/case.py\", line 322, in run\n    self.setUp()\n  File \"/Users/sidnarang/Desktop/JWC_SN/jenkins/2016-09-14_09-57-40.007266/classes/test_SeleniumDemo.py\", line 9, in setUp\n    self.driver = webdriver.Firefox()\n  File \"/Library/Python/2.7/site-packages/selenium/webdriver/firefox/webdriver.py\", line 80, in __init__\n    self.binary, timeout)\n  File \"/Library/Python/2.7/site-packages/selenium/webdriver/firefox/extension_connection.py\", line 52, in __init__\n    self.binary.launch_browser(self.profile, timeout=timeout)\n  File \"/Library/Python/2.7/site-packages/selenium/webdriver/firefox/firefox_binary.py\", line 68, in launch_browser\n    self._wait_until_connectable(timeout=timeout)\n  File \"/Library/Python/2.7/site-packages/selenium/webdriver/firefox/firefox_binary.py\", line 108, in _wait_until_connectable\n    % (self.profile.path))\nWebDriverException: Message: Can't load the profile. Profile Dir: /var/folders/rz/llsy0wqx4zn6qw066kpv7l8r0000gn/T/tmp56XwRj If you specified a log_file in the FirefoxBinary constructor, check it for details."}
{"label": "test_search_in_python_org", "file": "/Users/sidnarang/Desktop/JWC_SN/jenkins/2016-09-14_09-57-40.007266/classes/test_SeleniumDemo.py", "full_name": "test_SeleniumDemo.PythonOrgSearch.test_search_in_python_org", "status": "BROKEN", "description": null, "start_time": 1473872299.821897, "duration": 4.0582990646362305, "error_msg": "WebDriverException: Message: The browser appears to have exited before we could connect. If you specified a log_file in the FirefoxBinary constructor, check it for details.", "error_trace": "Traceback (most recent call last):\n  File \"/System/Library/Frameworks/Python.framework/Versions/2.7/lib/python2.7/unittest/case.py\", line 322, in run\n    self.setUp()\n  File \"/Users/sidnarang/Desktop/JWC_SN/jenkins/2016-09-14_09-57-40.007266/classes/test_SeleniumDemo.py\", line 9, in setUp\n    self.driver = webdriver.Firefox()\n  File \"/Library/Python/2.7/site-packages/selenium/webdriver/firefox/webdriver.py\", line 80, in __init__\n    self.binary, timeout)\n  File \"/Library/Python/2.7/site-packages/selenium/webdriver/firefox/extension_connection.py\", line 52, in __init__\n    self.binary.launch_browser(self.profile, timeout=timeout)\n  File \"/Library/Python/2.7/site-packages/selenium/webdriver/firefox/firefox_binary.py\", line 68, in launch_browser\n    self._wait_until_connectable(timeout=timeout)\n  File \"/Library/Python/2.7/site-packages/selenium/webdriver/firefox/firefox_binary.py\", line 99, in _wait_until_connectable\n    \"The browser appears to have exited \"\nWebDriverException: Message: The browser appears to have exited before we could connect. If you specified a log_file in the FirefoxBinary constructor, check it for details."}
{"label": "test_search_in_python_org", "file": "/Users/sidnarang/Desktop/JWC_SN/jenkins/2016-09-14_09-57-40.007266/classes/test_SeleniumDemo.py", "full_name": "test_SeleniumDemo.PythonOrgSearch.test_search_in_python_org", "status": "BROKEN", "description": null, "start_time": 1473872303.886201, "duration": 5.065582036972046, "error_msg": "WebDriverException: Message: The browser appears to have exited before we could connect. If you specified a log_file in the FirefoxBinary constructor, check it for details.", "error_trace": "Traceback (most recent call last):\n  File \"/System/Library/Frameworks/Python.framework/Versions/2.7/lib/python2.7/unittest/case.py\", line 322, in run\n    self.setUp()\n  File \"/Users/sidnarang/Desktop/JWC_SN/jenkins/2016-09-14_09-57-40.007266/classes/test_SeleniumDemo.py\", line 9, in setUp\n    self.driver = webdriver.Firefox()\n  File \"/Library/Python/2.7/site-packages/selenium/webdriver/firefox/webdriver.py\", line 80, in __init__\n    self.binary, timeout)\n  File \"/Library/Python/2.7/site-packages/selenium/webdriver/firefox/extension_connection.py\", line 52, in __init__\n    self.binary.launch_browser(self.profile, timeout=timeout)\n  File \"/Library/Python/2.7/site-packages/selenium/webdriver/firefox/firefox_binary.py\", line 68, in launch_browser\n    self._wait_until_connectable(timeout=timeout)\n  File \"/Library/Python/2.7/site-packages/selenium/webdriver/firefox/firefox_binary.py\", line 99, in _wait_until_connectable\n    \"The browser appears to have exited \"\nWebDriverException: Message: The browser appears to have exited before we could connect. If you specified a log_file in the FirefoxBinary constructor, check it for details."}
{"label": "test_search_in_python_org", "file": "/Users/sidnarang/Desktop/JWC_SN/jenkins/2016-09-14_09-57-40.007266/classes/test_SeleniumDemo.py", "full_name": "test_SeleniumDemo.PythonOrgSearch.test_search_in_python_org", "status": "BROKEN", "description": null, "start_time": 1473872308.958123, "duration": 4.062994956970215, "error_msg": "WebDriverException: Message: The browser appears to have exited before we could connect. If you specified a log_file in the FirefoxBinary constructor, check it for details.", "error_trace": "Traceback (most recent call last):\n  File \"/System/Library/Frameworks/Python.framework/Versions/2.7/lib/python2.7/unittest/case.py\", line 322, in run\n    self.setUp()\n  File \"/Users/sidnarang/Desktop/JWC_SN/jenkins/2016-09-14_09-57-40.007266/classes/test_SeleniumDemo.py\", line 9, in setUp\n    self.driver = webdriver.Firefox()\n  File \"/Library/Python/2.7/site-packages/selenium/webdriver/firefox/webdriver.py\", line 80, in __init__\n    self.binary, timeout)\n  File \"/Library/Python/2.7/site-packages/selenium/webdriver/firefox/extension_connection.py\", line 52, in __init__\n    self.binary.launch_browser(self.profile, timeout=timeout)\n  File \"/Library/Python/2.7/site-packages/selenium/webdriver/firefox/firefox_binary.py\", line 68, in launch_browser\n    self._wait_until_connectable(timeout=timeout)\n  File \"/Library/Python/2.7/site-packages/selenium/webdriver/firefox/firefox_binary.py\", line 99, in _wait_until_connectable\n    \"The browser appears to have exited \"\nWebDriverException: Message: The browser appears to have exited before we could connect. If you specified a log_file in the FirefoxBinary constructor, check it for details."}
{"label": "test_search_in_python_org", "file": "/Users/sidnarang/Desktop/JWC_SN/jenkins/2016-09-14_09-57-40.007266/classes/test_SeleniumDemo.py", "full_name": "test_SeleniumDemo.PythonOrgSearch.test_search_in_python_org", "status": "BROKEN", "description": null, "start_time": 1473872313.028021, "duration": 30.18787980079651, "error_msg": "WebDriverException: Message: Can't load the profile. Profile Dir: /var/folders/rz/llsy0wqx4zn6qw066kpv7l8r0000gn/T/tmphavZuu If you specified a log_file in the FirefoxBinary constructor, check it for details.", "error_trace": "Traceback (most recent call last):\n  File \"/System/Library/Frameworks/Python.framework/Versions/2.7/lib/python2.7/unittest/case.py\", line 322, in run\n    self.setUp()\n  File \"/Users/sidnarang/Desktop/JWC_SN/jenkins/2016-09-14_09-57-40.007266/classes/test_SeleniumDemo.py\", line 9, in setUp\n    self.driver = webdriver.Firefox()\n  File \"/Library/Python/2.7/site-packages/selenium/webdriver/firefox/webdriver.py\", line 80, in __init__\n    self.binary, timeout)\n  File \"/Library/Python/2.7/site-packages/selenium/webdriver/firefox/extension_connection.py\", line 52, in __init__\n    self.binary.launch_browser(self.profile, timeout=timeout)\n  File \"/Library/Python/2.7/site-packages/selenium/webdriver/firefox/firefox_binary.py\", line 68, in launch_browser\n    self._wait_until_connectable(timeout=timeout)\n  File \"/Library/Python/2.7/site-packages/selenium/webdriver/firefox/firefox_binary.py\", line 108, in _wait_until_connectable\n    % (self.profile.path))\nWebDriverException: Message: Can't load the profile. Profile Dir: /var/folders/rz/llsy0wqx4zn6qw066kpv7l8r0000gn/T/tmphavZuu If you specified a log_file in the FirefoxBinary constructor, check it for details."}
{"label": "test_search_in_python_org", "file": "/Users/sidnarang/Desktop/JWC_SN/jenkins/2016-09-14_09-57-40.007266/classes/test_SeleniumDemo.py", "full_name": "test_SeleniumDemo.PythonOrgSearch.test_search_in_python_org", "status": "BROKEN", "description": null, "start_time": 1473872343.220498, "duration": 5.0624589920043945, "error_msg": "WebDriverException: Message: The browser appears to have exited before we could connect. If you specified a log_file in the FirefoxBinary constructor, check it for details.", "error_trace": "Traceback (most recent call last):\n  File \"/System/Library/Frameworks/Python.framework/Versions/2.7/lib/python2.7/unittest/case.py\", line 322, in run\n    self.setUp()\n  File \"/Users/sidnarang/Desktop/JWC_SN/jenkins/2016-09-14_09-57-40.007266/classes/test_SeleniumDemo.py\", line 9, in setUp\n    self.driver = webdriver.Firefox()\n  File \"/Library/Python/2.7/site-packages/selenium/webdriver/firefox/webdriver.py\", line 80, in __init__\n    self.binary, timeout)\n  File \"/Library/Python/2.7/site-packages/selenium/webdriver/firefox/extension_connection.py\", line 52, in __init__\n    self.binary.launch_browser(self.profile, timeout=timeout)\n  File \"/Library/Python/2.7/site-packages/selenium/webdriver/firefox/firefox_binary.py\", line 68, in launch_browser\n    self._wait_until_connectable(timeout=timeout)\n  File \"/Library/Python/2.7/site-packages/selenium/webdriver/firefox/firefox_binary.py\", line 99, in _wait_until_connectable\n    \"The browser appears to have exited \"\nWebDriverException: Message: The browser appears to have exited before we could connect. If you specified a log_file in the FirefoxBinary constructor, check it for details."}
{"label": "test_search_in_python_org", "file": "/Users/sidnarang/Desktop/JWC_SN/jenkins/2016-09-14_09-57-40.007266/classes/test_SeleniumDemo.py", "full_name": "test_SeleniumDemo.PythonOrgSearch.test_search_in_python_org", "status": "BROKEN", "description": null, "start_time": 1473872348.28972, "duration": 3.0534749031066895, "error_msg": "WebDriverException: Message: The browser appears to have exited before we could connect. If you specified a log_file in the FirefoxBinary constructor, check it for details.", "error_trace": "Traceback (most recent call last):\n  File \"/System/Library/Frameworks/Python.framework/Versions/2.7/lib/python2.7/unittest/case.py\", line 322, in run\n    self.setUp()\n  File \"/Users/sidnarang/Desktop/JWC_SN/jenkins/2016-09-14_09-57-40.007266/classes/test_SeleniumDemo.py\", line 9, in setUp\n    self.driver = webdriver.Firefox()\n  File \"/Library/Python/2.7/site-packages/selenium/webdriver/firefox/webdriver.py\", line 80, in __init__\n    self.binary, timeout)\n  File \"/Library/Python/2.7/site-packages/selenium/webdriver/firefox/extension_connection.py\", line 52, in __init__\n    self.binary.launch_browser(self.profile, timeout=timeout)\n  File \"/Library/Python/2.7/site-packages/selenium/webdriver/firefox/firefox_binary.py\", line 68, in launch_browser\n    self._wait_until_connectable(timeout=timeout)\n  File \"/Library/Python/2.7/site-packages/selenium/webdriver/firefox/firefox_binary.py\", line 99, in _wait_until_connectable\n    \"The browser appears to have exited \"\nWebDriverException: Message: The browser appears to have exited before we could connect. If you specified a log_file in the FirefoxBinary constructor, check it for details."}
{"label": "test_search_in_python_org", "file": "/Users/sidnarang/Desktop/JWC_SN/jenkins/2016-09-14_09-57-40.007266/classes/test_SeleniumDemo.py", "full_name": "test_SeleniumDemo.PythonOrgSearch.test_search_in_python_org", "status": "BROKEN", "description": null, "start_time": 1473872351.349276, "duration": 9.067948818206787, "error_msg": "WebDriverException: Message: The browser appears to have exited before we could connect. If you specified a log_file in the FirefoxBinary constructor, check it for details.", "error_trace": "Traceback (most recent call last):\n  File \"/System/Library/Frameworks/Python.framework/Versions/2.7/lib/python2.7/unittest/case.py\", line 322, in run\n    self.setUp()\n  File \"/Users/sidnarang/Desktop/JWC_SN/jenkins/2016-09-14_09-57-40.007266/classes/test_SeleniumDemo.py\", line 9, in setUp\n    self.driver = webdriver.Firefox()\n  File \"/Library/Python/2.7/site-packages/selenium/webdriver/firefox/webdriver.py\", line 80, in __init__\n    self.binary, timeout)\n  File \"/Library/Python/2.7/site-packages/selenium/webdriver/firefox/extension_connection.py\", line 52, in __init__\n    self.binary.launch_browser(self.profile, timeout=timeout)\n  File \"/Library/Python/2.7/site-packages/selenium/webdriver/firefox/firefox_binary.py\", line 68, in launch_browser\n    self._wait_until_connectable(timeout=timeout)\n  File \"/Library/Python/2.7/site-packages/selenium/webdriver/firefox/firefox_binary.py\", line 99, in _wait_until_connectable\n    \"The browser appears to have exited \"\nWebDriverException: Message: The browser appears to have exited before we could connect. If you specified a log_file in the FirefoxBinary constructor, check it for details."}
{"label": "test_search_in_python_org", "file": "/Users/sidnarang/Desktop/JWC_SN/jenkins/2016-09-14_09-57-40.007266/classes/test_SeleniumDemo.py", "full_name": "test_SeleniumDemo.PythonOrgSearch.test_search_in_python_org", "status": "BROKEN", "description": null, "start_time": 1473872360.423386, "duration": 4.070452928543091, "error_msg": "WebDriverException: Message: The browser appears to have exited before we could connect. If you specified a log_file in the FirefoxBinary constructor, check it for details.", "error_trace": "Traceback (most recent call last):\n  File \"/System/Library/Frameworks/Python.framework/Versions/2.7/lib/python2.7/unittest/case.py\", line 322, in run\n    self.setUp()\n  File \"/Users/sidnarang/Desktop/JWC_SN/jenkins/2016-09-14_09-57-40.007266/classes/test_SeleniumDemo.py\", line 9, in setUp\n    self.driver = webdriver.Firefox()\n  File \"/Library/Python/2.7/site-packages/selenium/webdriver/firefox/webdriver.py\", line 80, in __init__\n    self.binary, timeout)\n  File \"/Library/Python/2.7/site-packages/selenium/webdriver/firefox/extension_connection.py\", line 52, in __init__\n    self.binary.launch_browser(self.profile, timeout=timeout)\n  File \"/Library/Python/2.7/site-packages/selenium/webdriver/firefox/firefox_binary.py\", line 68, in launch_browser\n    self._wait_until_connectable(timeout=timeout)\n  File \"/Library/Python/2.7/site-packages/selenium/webdriver/firefox/firefox_binary.py\", line 99, in _wait_until_connectable\n    \"The browser appears to have exited \"\nWebDriverException: Message: The browser appears to have exited before we could connect. If you specified a log_file in the FirefoxBinary constructor, check it for details."}
{"label": "test_search_in_python_org", "file": "/Users/sidnarang/Desktop/JWC_SN/jenkins/2016-09-14_09-57-40.007266/classes/test_SeleniumDemo.py", "full_name": "test_SeleniumDemo.PythonOrgSearch.test_search_in_python_org", "status": "BROKEN", "description": null, "start_time": 1473872364.499074, "duration": 3.0592100620269775, "error_msg": "WebDriverException: Message: The browser appears to have exited before we could connect. If you specified a log_file in the FirefoxBinary constructor, check it for details.", "error_trace": "Traceback (most recent call last):\n  File \"/System/Library/Frameworks/Python.framework/Versions/2.7/lib/python2.7/unittest/case.py\", line 322, in run\n    self.setUp()\n  File \"/Users/sidnarang/Desktop/JWC_SN/jenkins/2016-09-14_09-57-40.007266/classes/test_SeleniumDemo.py\", line 9, in setUp\n    self.driver = webdriver.Firefox()\n  File \"/Library/Python/2.7/site-packages/selenium/webdriver/firefox/webdriver.py\", line 80, in __init__\n    self.binary, timeout)\n  File \"/Library/Python/2.7/site-packages/selenium/webdriver/firefox/extension_connection.py\", line 52, in __init__\n    self.binary.launch_browser(self.profile, timeout=timeout)\n  File \"/Library/Python/2.7/site-packages/selenium/webdriver/firefox/firefox_binary.py\", line 68, in launch_browser\n    self._wait_until_connectable(timeout=timeout)\n  File \"/Library/Python/2.7/site-packages/selenium/webdriver/firefox/firefox_binary.py\", line 99, in _wait_until_connectable\n    \"The browser appears to have exited \"\nWebDriverException: Message: The browser appears to have exited before we could connect. If you specified a log_file in the FirefoxBinary constructor, check it for details."}
{"label": "test_search_in_python_org", "file": "/Users/sidnarang/Desktop/JWC_SN/jenkins/2016-09-14_09-57-40.007266/classes/test_SeleniumDemo.py", "full_name": "test_SeleniumDemo.PythonOrgSearch.test_search_in_python_org", "status": "BROKEN", "description": null, "start_time": 1473872367.564437, "duration": 4.06511116027832, "error_msg": "WebDriverException: Message: The browser appears to have exited before we could connect. If you specified a log_file in the FirefoxBinary constructor, check it for details.", "error_trace": "Traceback (most recent call last):\n  File \"/System/Library/Frameworks/Python.framework/Versions/2.7/lib/python2.7/unittest/case.py\", line 322, in run\n    self.setUp()\n  File \"/Users/sidnarang/Desktop/JWC_SN/jenkins/2016-09-14_09-57-40.007266/classes/test_SeleniumDemo.py\", line 9, in setUp\n    self.driver = webdriver.Firefox()\n  File \"/Library/Python/2.7/site-packages/selenium/webdriver/firefox/webdriver.py\", line 80, in __init__\n    self.binary, timeout)\n  File \"/Library/Python/2.7/site-packages/selenium/webdriver/firefox/extension_connection.py\", line 52, in __init__\n    self.binary.launch_browser(self.profile, timeout=timeout)\n  File \"/Library/Python/2.7/site-packages/selenium/webdriver/firefox/firefox_binary.py\", line 68, in launch_browser\n    self._wait_until_connectable(timeout=timeout)\n  File \"/Library/Python/2.7/site-packages/selenium/webdriver/firefox/firefox_binary.py\", line 99, in _wait_until_connectable\n    \"The browser appears to have exited \"\nWebDriverException: Message: The browser appears to have exited before we could connect. If you specified a log_file in the FirefoxBinary constructor, check it for details."}
{"label": "test_search_in_python_org", "file": "/Users/sidnarang/Desktop/JWC_SN/jenkins/2016-09-14_09-57-40.007266/classes/test_SeleniumDemo.py", "full_name": "test_SeleniumDemo.PythonOrgSearch.test_search_in_python_org", "status": "BROKEN", "description": null, "start_time": 1473872371.637692, "duration": 5.066359043121338, "error_msg": "WebDriverException: Message: The browser appears to have exited before we could connect. If you specified a log_file in the FirefoxBinary constructor, check it for details.", "error_trace": "Traceback (most recent call last):\n  File \"/System/Library/Frameworks/Python.framework/Versions/2.7/lib/python2.7/unittest/case.py\", line 322, in run\n    self.setUp()\n  File \"/Users/sidnarang/Desktop/JWC_SN/jenkins/2016-09-14_09-57-40.007266/classes/test_SeleniumDemo.py\", line 9, in setUp\n    self.driver = webdriver.Firefox()\n  File \"/Library/Python/2.7/site-packages/selenium/webdriver/firefox/webdriver.py\", line 80, in __init__\n    self.binary, timeout)\n  File \"/Library/Python/2.7/site-packages/selenium/webdriver/firefox/extension_connection.py\", line 52, in __init__\n    self.binary.launch_browser(self.profile, timeout=timeout)\n  File \"/Library/Python/2.7/site-packages/selenium/webdriver/firefox/firefox_binary.py\", line 68, in launch_browser\n    self._wait_until_connectable(timeout=timeout)\n  File \"/Library/Python/2.7/site-packages/selenium/webdriver/firefox/firefox_binary.py\", line 99, in _wait_until_connectable\n    \"The browser appears to have exited \"\nWebDriverException: Message: The browser appears to have exited before we could connect. If you specified a log_file in the FirefoxBinary constructor, check it for details."}
{"label": "test_search_in_python_org", "file": "/Users/sidnarang/Desktop/JWC_SN/jenkins/2016-09-14_09-57-40.007266/classes/test_SeleniumDemo.py", "full_name": "test_SeleniumDemo.PythonOrgSearch.test_search_in_python_org", "status": "BROKEN", "description": null, "start_time": 1473872376.710253, "duration": 30.217494010925293, "error_msg": "WebDriverException: Message: Can't load the profile. Profile Dir: /var/folders/rz/llsy0wqx4zn6qw066kpv7l8r0000gn/T/tmpTrb6F9 If you specified a log_file in the FirefoxBinary constructor, check it for details.", "error_trace": "Traceback (most recent call last):\n  File \"/System/Library/Frameworks/Python.framework/Versions/2.7/lib/python2.7/unittest/case.py\", line 322, in run\n    self.setUp()\n  File \"/Users/sidnarang/Desktop/JWC_SN/jenkins/2016-09-14_09-57-40.007266/classes/test_SeleniumDemo.py\", line 9, in setUp\n    self.driver = webdriver.Firefox()\n  File \"/Library/Python/2.7/site-packages/selenium/webdriver/firefox/webdriver.py\", line 80, in __init__\n    self.binary, timeout)\n  File \"/Library/Python/2.7/site-packages/selenium/webdriver/firefox/extension_connection.py\", line 52, in __init__\n    self.binary.launch_browser(self.profile, timeout=timeout)\n  File \"/Library/Python/2.7/site-packages/selenium/webdriver/firefox/firefox_binary.py\", line 68, in launch_browser\n    self._wait_until_connectable(timeout=timeout)\n  File \"/Library/Python/2.7/site-packages/selenium/webdriver/firefox/firefox_binary.py\", line 108, in _wait_until_connectable\n    % (self.profile.path))\nWebDriverException: Message: Can't load the profile. Profile Dir: /var/folders/rz/llsy0wqx4zn6qw066kpv7l8r0000gn/T/tmpTrb6F9 If you specified a log_file in the FirefoxBinary constructor, check it for details."}
{"label": "test_search_in_python_org", "file": "/Users/sidnarang/Desktop/JWC_SN/jenkins/2016-09-14_09-57-40.007266/classes/test_SeleniumDemo.py", "full_name": "test_SeleniumDemo.PythonOrgSearch.test_search_in_python_org", "status": "BROKEN", "description": null, "start_time": 1473872406.932341, "duration": 15.090147972106934, "error_msg": "WebDriverException: Message: The browser appears to have exited before we could connect. If you specified a log_file in the FirefoxBinary constructor, check it for details.", "error_trace": "Traceback (most recent call last):\n  File \"/System/Library/Frameworks/Python.framework/Versions/2.7/lib/python2.7/unittest/case.py\", line 322, in run\n    self.setUp()\n  File \"/Users/sidnarang/Desktop/JWC_SN/jenkins/2016-09-14_09-57-40.007266/classes/test_SeleniumDemo.py\", line 9, in setUp\n    self.driver = webdriver.Firefox()\n  File \"/Library/Python/2.7/site-packages/selenium/webdriver/firefox/webdriver.py\", line 80, in __init__\n    self.binary, timeout)\n  File \"/Library/Python/2.7/site-packages/selenium/webdriver/firefox/extension_connection.py\", line 52, in __init__\n    self.binary.launch_browser(self.profile, timeout=timeout)\n  File \"/Library/Python/2.7/site-packages/selenium/webdriver/firefox/firefox_binary.py\", line 68, in launch_browser\n    self._wait_until_connectable(timeout=timeout)\n  File \"/Library/Python/2.7/site-packages/selenium/webdriver/firefox/firefox_binary.py\", line 99, in _wait_until_connectable\n    \"The browser appears to have exited \"\nWebDriverException: Message: The browser appears to have exited before we could connect. If you specified a log_file in the FirefoxBinary constructor, check it for details."}
{"label": "test_search_in_python_org", "file": "/Users/sidnarang/Desktop/JWC_SN/jenkins/2016-09-14_09-57-40.007266/classes/test_SeleniumDemo.py", "full_name": "test_SeleniumDemo.PythonOrgSearch.test_search_in_python_org", "status": "BROKEN", "description": null, "start_time": 1473872422.027582, "duration": 8.071211099624634, "error_msg": "WebDriverException: Message: The browser appears to have exited before we could connect. If you specified a log_file in the FirefoxBinary constructor, check it for details.", "error_trace": "Traceback (most recent call last):\n  File \"/System/Library/Frameworks/Python.framework/Versions/2.7/lib/python2.7/unittest/case.py\", line 322, in run\n    self.setUp()\n  File \"/Users/sidnarang/Desktop/JWC_SN/jenkins/2016-09-14_09-57-40.007266/classes/test_SeleniumDemo.py\", line 9, in setUp\n    self.driver = webdriver.Firefox()\n  File \"/Library/Python/2.7/site-packages/selenium/webdriver/firefox/webdriver.py\", line 80, in __init__\n    self.binary, timeout)\n  File \"/Library/Python/2.7/site-packages/selenium/webdriver/firefox/extension_connection.py\", line 52, in __init__\n    self.binary.launch_browser(self.profile, timeout=timeout)\n  File \"/Library/Python/2.7/site-packages/selenium/webdriver/firefox/firefox_binary.py\", line 68, in launch_browser\n    self._wait_until_connectable(timeout=timeout)\n  File \"/Library/Python/2.7/site-packages/selenium/webdriver/firefox/firefox_binary.py\", line 99, in _wait_until_connectable\n    \"The browser appears to have exited \"\nWebDriverException: Message: The browser appears to have exited before we could connect. If you specified a log_file in the FirefoxBinary constructor, check it for details."}
